Workbook

Sheet Summary
B2: Yours Legally, — Cost estimation summary
B3: Gemini API · today's volume from the Inputs sheet · all figures in USD per month unless stated
B5: Running cost
B6: Metric | C6: Value | D6: What it means
B7: AI cost per deal (average, excl. eval runs) | C7: =Inference!$M$45 -> 0.36363203 | D7: Reviews, re-checks, register updates and seller checks averaged over deals.
B8: AI cost per full-review deal (main + supporting docs) | C8: =Inference!$M$20 -> 0.503937 | D8: Fixed pipeline of model calls per document; rules run as code.
B9: AI cost per NDA (fast lane) | C9: =Inference!$O$19 -> 0.022881
B10: Inference per month | C10: =Inference!$M$43 -> 15.642616
B11: Embeddings per month | C11: =Embeddings!$F$20 -> 0.001861189 | D11: Clause index updates + query embeddings: tiny.
B12: AI running cost per month | C12: ='Cost Savings'!$C$68 -> 15.644477 | D12: Inference + embeddings
B13: Platform per month (production only) | C13: =Inputs!$C$54 -> 39 | D13: Hosting + database + sign-in; $0 for the capstone on Vercel Hobby.
B14: Total running cost per month (production) | C14: ='Cost Savings'!$C$73 -> 54.644477
B15: Inference per month at growth volume | C15: =Inference!$M$44 -> 20.0062 | D15: ~20 contracts/month (PRD §8).
B17: Savings
B18: Metric | C18: Value | D18: What it means
B19: Karandeep's hours on contracts: today | C19: ='Cost Savings'!$C$16 -> 18.5 | D19: Hours per month
B20: Karandeep's hours on contracts: with Yours Legally | C20: ='Cost Savings'!$C$25 -> 3.1269608 | D20: Hours per month
B21: Share of his contract time given back | C21: ='Cost Savings'!$C$30 -> 0.83097509
B22: Total savings per month (base case) | C22: ='Cost Savings'!$C$66 -> 1336.1496 | D22: CEO time + seller time + counsel − AI cost (template scope)
B23: % savings vs manual review | C23: ='Cost Savings'!$C$67 -> 0.64991542
B24: Return per $1 of AI cost | C24: ='Cost Savings'!$C$69 -> 85.407112
B25: Savings per month after production platform costs | C25: ='Cost Savings'!$C$74 -> 1297.1496
B26: Return per $1 of total running cost (production) | C26: ='Cost Savings'!$C$75 -> 24.451687
B27: Savings per month incl. risk and revenue protected | C27: ='Cost Savings'!$C$89 -> 3773.6496 | D27: Adds the expected value of avoided incidents and lost deals
B28: One-time setup cost | C28: ='Cost Savings'!$C$98 -> 87.636439 | D28: Register + clause index backfill + Karandeep's verification time
B29: Payback (months) | C29: ='Cost Savings'!$C$99 -> 0.065588791

Sheet Inputs
B2: Yours Legally, — Cost estimation inputs (measured tokens)
B3: Blue = input you can change · black = formula · green = linked from another sheet · yellow fill = key assumption to sanity-check
B5: 1. Volume (per month)
B6: Contracts (deals) reviewed per month (today) | C6: 8 | D6: Client interview: about 3 to 4 contracts plus 4 to 5 NDAs a month.
B7: Share of deals that are NDA-only | C7: 0.5625 | D7: Client meeting 2: 4.5 NDAs of about 8 documents a month.
B8: Real contract length vs the dataset samples (x) | C8: 3 | D8: Client meeting 2: samples are about 4 pages; real contracts 10 to 15 pages. Multiplies the tokens of steps that read the whole document.
B9: Full-review deals per month (MSA, SOW, partnership, AtliQ paper…) | C9: =C6*(1-C7) -> 3.5 | D9: Formula
B10: NDA fast-lane reviews per month | C10: =C6*C7 -> 4.5 | D10: Formula
B11: Supporting documents per full-review deal (BAA, DPA, annex, waiver…) | C11: 1 | D11: Assumption: every full-review deal has at least one supporting compliance document, annex or waiver → 2 documents per deal in total. (The dataset averages 1.15 only because supporting documents were MISSING, which is the problem we're solving.)
B12: Share of documents that arrive as scans (read by OCR) | C12: 0.2 | D12: Assumption: some clients send scanned PDFs; only those need the OCR step.
B13: Brief versions per deal (incl. re-checks) | C13: 1.5 | D13: Assumption: half of deals get one revised draft or added input (FR-17).
B14: Share of a re-check served from cache | C14: 0.4 | D14: Assumption: unchanged documents and steps reuse cached results (cache by document hash).
B15: New contracts signed per month (added to the register) | C15: 6 | D15: Assumption: most reviewed deals get signed; each signed contract is extracted into the register (FR-1).
B16: Seller deal checks per month (incl. re-runs) | C16: 12 | D16: Assumption: one check per new deal plus re-runs after banners (FR-13, FR-19).
B17: Growth scenario: deals per month | C17: 20 | D17: PRD §8: design for ~20 contracts/month (2× today).
B19: 2. Conflict check and evals
B20: Register entries passed to each conflict check (after the code filter) | C20: 3 | D20: Measured on the prototype: 0–2 candidates per contract with 57 entries (review log). 3 = headroom. Raise it to model hundreds of contracts (e.g. 8–10).
B21: Tokens per register entry sent to the model | C21: 400 | D21: Entry summary + verbatim source quote + scope fields.
B22: Conflict check: other input tokens (prompt + relevant contract clauses) | C22: 3400 | D22: MEASURED: conflict calls averaged ~4,600 input tokens with the prototype's candidates; 3,400 + 3 x 400.
B23: Full eval-set runs per month | C23: 4 | D23: Each run = all 50 eval cases. Weekly regression before releases (PRD §14 Stage 1). Not '4 evals'.
B24: Repeats per eval run (consistency check) | C24: 1 | D24: Set to 3 when running the consistency test (--repeat 3, PRD §11).
B25: AI documents per eval run: main agreements (full review) | C25: 11 | D25: Dataset: 15 incoming documents = 11 main agreements + 1 supporting (Harrington BAA) + 3 NDAs. The other eval cases (linking, access, register) run as code: $0.
B26: AI documents per eval run: supporting documents | C26: 1 | D26: Harrington BAA
B27: AI documents per eval run: NDAs | C27: 3 | D27: FinServe, LoopMart, Ortiz NDA
B29: 3. Model prices: Gemini API paid tier, $ per 1M tokens (output price includes thinking tokens)
B30: Model | C30: Input $/1M | D30: Output $/1M | E30: Notes
B31: Gemini 3.5 Flash | C31: 1.5 | D31: 9 | E31: Strong model used in the build (gemini-3.5-flash)
B32: Gemini 3.5 Flash-Lite | C32: 0.3 | D32: 2.5 | E32: Fast model used in the build
B33: Gemini 3.8 Flash (to 31 Dec 2026) | C33: 0.75 | D33: 3.75 | E33: Introductory price until 31 Dec 2026
B34: Gemini 3.8 Flash (from 1 Jan 2027) | C34: 1.5 | D34: 7.5 | E34: Standard price from 1 Jan 2027
B35: Gemini 3.1 Flash-Lite | C35: 0.25 | D35: 1.5 | E35: Cheapest option
B36: Gemini 3 Flash Preview | C36: 0.5 | D36: 3 | E36: Preview model
B37: gemini-embedding-001 (embeddings, input only) | C37: 0.15 | D37: 0 | E37: Embedding price per 1M input tokens
B38: Source: ai.google.dev/gemini-api/docs/pricing (checked 5 Oct 2026); embeddings: Google Developers Blog, Gemini Embedding GA. The free tier exists but rate-limits; costs here use paid prices.
B40: 4. Model selection (pick from the list)
B41: Strong model: conflicts, playbook, NDA check, brief, register | C41: Gemini 3.5 Flash | D41: As built (LLM_MODEL_STRONG).
B42: Fast model: extraction, notes, 'how it differs', seller checks | C42: Gemini 3.5 Flash-Lite | D42: As built (LLM_MODEL_FAST).
B43: Strong: input $/1M | C43: =INDEX($C$31:$C$36,MATCH($C$41,$B$31:$B$36,0)) -> 1.5
B44: Strong: output $/1M | C44: =INDEX($D$31:$D$36,MATCH($C$41,$B$31:$B$36,0)) -> 9
B45: Fast: input $/1M | C45: =INDEX($C$31:$C$36,MATCH($C$42,$B$31:$B$36,0)) -> 0.3
...

Sheet Inference
B2: Inference: what each AI call costs
B3: In a RAG chatbot, inference = answering one user query. Here the unit is ONE DEAL REVIEW: a fixed pipeline of model calls (our 'tool calls'). Steps marked Code are rule checks: $0.
B5: A. Cost per review, step by step
B6: Pipeline step | C6: Feature / FR | D6: Model tier | E6: Input tokens per call | F6: Output tokens per call (incl. thinking) | G6: Calls per MAIN agreement (incl. once-per-deal steps) | H6: Calls per SUPPORTING document | I6: Calls per NDA | J6: Input $/1M | K6: Output $/1M | L6: Cost per call ($) | M6: Cost per main agreement ($) | N6: Cost per supporting doc ($) | O6: Cost per NDA ($) | P6: What happens in this step / basis for tokens
B7: 1. Intake: extract contract facts with source quotes | C7: F2 · FR-3, FR-4 | D7: Fast | E7: =3100*Inputs!$C$8 -> 9300 | F7: =900*Inputs!$C$8 -> 2700 | G7: 1 | H7: 1 | I7: 1 | J7: =IF(D7="Strong",Inputs!$C$43,IF(D7="Fast",Inputs!$C$45,0)) -> 0.3 | K7: =IF(D7="Strong",Inputs!$C$44,IF(D7="Fast",Inputs!$C$46,0)) -> 2.5 | L7: =E7*J7/1000000+F7*K7/1000000 -> 0.00954 | M7: =L7*G7 -> 0.00954 | N7: =L7*H7 -> 0.00954 | O7: =L7*I7 -> 0.00954 | P7: MEASURED (Gemini flash-lite, 14 calls): ~2,800-3,900 in / ~900 out. Reads the whole document; returns facts with source quotes.
B8: 1b. OCR for scanned files (only when the file is a scan) | C8: F2 · FR-3 | D8: Fast | E8: =1200*Inputs!$C$8 -> 3600 | F8: =900*Inputs!$C$8 -> 2700 | G8: =Inputs!$C$12 -> 0.2 | H8: =Inputs!$C$12 -> 0.2 | I8: =Inputs!$C$12 -> 0.2 | J8: =IF(D8="Strong",Inputs!$C$43,IF(D8="Fast",Inputs!$C$45,0)) -> 0.3 | K8: =IF(D8="Strong",Inputs!$C$44,IF(D8="Fast",Inputs!$C$46,0)) -> 2.5 | L8: =E8*J8/1000000+F8*K8/1000000 -> 0.00783 | M8: =L8*G8 -> 0.001566 | N8: =L8*H8 -> 0.001566 | O8: =L8*I8 -> 0.001566 | P8: MEASURED (2 calls): ~1,200 in / ~900 out. Runs only for scans, so calls = share of scanned documents (Inputs).
B9: 2. Gate rules (entity, law, payment, caps, annexes) | C9: F2 · FR-4 | D9: Code | E9: 0 | F9: 0 | G9: 1 | H9: 1 | I9: 1 | J9: =IF(D9="Strong",Inputs!$C$43,IF(D9="Fast",Inputs!$C$45,0)) -> 0 | K9: =IF(D9="Strong",Inputs!$C$44,IF(D9="Fast",Inputs!$C$46,0)) -> 0 | L9: =E9*J9/1000000+F9*K9/1000000 -> 0 | M9: =L9*G9 -> 0 | N9: =L9*H9 -> 0 | O9: =L9*I9 -> 0 | P9: Plain rules over the extracted facts: no model call.
B10: 3. Conflict check against the register | C10: F3 · FR-6 | D10: Strong | E10: =Inputs!$C$22*Inputs!$C$8+Inputs!$C$20*Inputs!$C$21 -> 11400 | F10: 7000 | G10: 1 | H10: 1 | I10: 0 | J10: =IF(D10="Strong",Inputs!$C$43,IF(D10="Fast",Inputs!$C$45,0)) -> 1.5 | K10: =IF(D10="Strong",Inputs!$C$44,IF(D10="Fast",Inputs!$C$46,0)) -> 9 | L10: =E10*J10/1000000+F10*K10/1000000 -> 0.0801 | M10: =L10*G10 -> 0.0801 | N10: =L10*H10 -> 0.0801 | O10: =L10*I10 -> 0 | P10: MEASURED (5 calls): ~4,400-5,000 in / ~5,900-9,800 out. Code filters the register first; the model judges only the candidates. Most output is thinking.
B11: 4. NDA mutuality checklist + covenant scan | C11: F4 · FR-5, FR-8 | D11: Strong | E11: 1400 | F11: 650 | G11: 0 | H11: 0 | I11: 1 | J11: =IF(D11="Strong",Inputs!$C$43,IF(D11="Fast",Inputs!$C$45,0)) -> 1.5 | K11: =IF(D11="Strong",Inputs!$C$44,IF(D11="Fast",Inputs!$C$46,0)) -> 9 | L11: =E11*J11/1000000+F11*K11/1000000 -> 0.00795 | M11: =L11*G11 -> 0 | N11: =L11*H11 -> 0 | O11: =L11*I11 -> 0.00795 | P11: MEASURED (2 calls): ~1,400 in / ~500-800 out. NDA fast lane, low thinking.
B12: 5. Playbook & fairness (mirror, flow-down) | C12: F4 · FR-7 | D12: Strong | E12: =5200*Inputs!$C$8 -> 15600 | F12: 6600 | G12: 1 | H12: 1 | I12: 0 | J12: =IF(D12="Strong",Inputs!$C$43,IF(D12="Fast",Inputs!$C$45,0)) -> 1.5 | K12: =IF(D12="Strong",Inputs!$C$44,IF(D12="Fast",Inputs!$C$46,0)) -> 9 | L12: =E12*J12/1000000+F12*K12/1000000 -> 0.0828 | M12: =L12*G12 -> 0.0828 | N12: =L12*H12 -> 0.0828 | O12: =L12*I12 -> 0 | P12: MEASURED (10 calls): ~5,200 in / ~5,900-13,400 out. Key clauses vs the playbook; the heaviest step.
B13: 6. Similar past clauses: vector search | C13: F4 · FR-22 | D13: Code | E13: 0 | F13: 0 | G13: 1 | H13: 1 | I13: 0 | J13: =IF(D13="Strong",Inputs!$C$43,IF(D13="Fast",Inputs!$C$45,0)) -> 0 | K13: =IF(D13="Strong",Inputs!$C$44,IF(D13="Fast",Inputs!$C$46,0)) -> 0 | L13: =E13*J13/1000000+F13*K13/1000000 -> 0 | M13: =L13*G13 -> 0 | N13: =L13*H13 -> 0 | O13: =L13*I13 -> 0 | P13: Cosine similarity in code over the clause index. Query embeddings are on the Embeddings sheet.
B14: 7. Similar past clauses: 'how it differs' lines | C14: F4 · FR-22 | D14: Strong | E14: =3500*Inputs!$C$8 -> 10500 | F14: 5900 | G14: 1 | H14: 1 | I14: 0 | J14: =IF(D14="Strong",Inputs!$C$43,IF(D14="Fast",Inputs!$C$45,0)) -> 1.5 | K14: =IF(D14="Strong",Inputs!$C$44,IF(D14="Fast",Inputs!$C$46,0)) -> 9 | L14: =E14*J14/1000000+F14*K14/1000000 -> 0.06885 | M14: =L14*G14 -> 0.06885 | N14: =L14*H14 -> 0.06885 | O14: =L14*I14 -> 0 | P14: MEASURED (3 calls): ~2,700-3,800 in / ~3,800-6,900 out. Runs on the strong model in the build; moving it to the fast model with low thinking is the easiest saving.
B15: 8. Bundle: required documents per party | C15: F5 · FR-9 | D15: Code | E15: 0 | F15: 0 | G15: 1 | H15: 0 | I15: 1 | J15: =IF(D15="Strong",Inputs!$C$43,IF(D15="Fast",Inputs!$C$45,0)) -> 0 | K15: =IF(D15="Strong",Inputs!$C$44,IF(D15="Fast",Inputs!$C$46,0)) -> 0 | L15: =E15*J15/1000000+F15*K15/1000000 -> 0 | M15: =L15*G15 -> 0 | N15: =L15*H15 -> 0 | O15: =L15*I15 -> 0 | P15: Rules over the deal's documents (once per deal): no model call.
B16: 9. Bundle: facts from meeting notes | C16: F5 · FR-10 | D16: Strong | E16: 600 | F16: 1500 | G16: 1 | H16: 0 | I16: 0 | J16: =IF(D16="Strong",Inputs!$C$43,IF(D16="Fast",Inputs!$C$45,0)) -> 1.5 | K16: =IF(D16="Strong",Inputs!$C$44,IF(D16="Fast",Inputs!$C$46,0)) -> 9 | L16: =E16*J16/1000000+F16*K16/1000000 -> 0.0144 | M16: =L16*G16 -> 0.0144 | N16: =L16*H16 -> 0 | O16: =L16*I16 -> 0 | P16: MEASURED (10 calls): ~200-700 in / ~1,000-1,700 out. Once per deal.
B17: 10. Verdict | C17: F6 | D17: Code | E17: 0 | F17: 0 | G17: 1 | H17: 0 | I17: 1 | J17: =IF(D17="Strong",Inputs!$C$43,IF(D17="Fast",Inputs!$C$45,0)) -> 0 | K17: =IF(D17="Strong",Inputs!$C$44,IF(D17="Fast",Inputs!$C$46,0)) -> 0 | L17: =E17*J17/1000000+F17*K17/1000000 -> 0 | M17: =L17*G17 -> 0 | N17: =L17*H17 -> 0 | O17: =L17*I17 -> 0 | P17: Computed by code from all findings, once per deal: no model call.
B18: 11. Brief wording from findings JSON | C18: F6 · FR-11 | D18: Strong | E18: 450 | F18: 350 | G18: 1 | H18: 0 | I18: 1 | J18: =IF(D18="Strong",Inputs!$C$43,IF(D18="Fast",Inputs!$C$45,0)) -> 1.5 | K18: =IF(D18="Strong",Inputs!$C$44,IF(D18="Fast",Inputs!$C$46,0)) -> 9 | L18: =E18*J18/1000000+F18*K18/1000000 -> 0.003825 | M18: =L18*G18 -> 0.003825 | N18: =L18*H18 -> 0 | O18: =L18*I18 -> 0.003825 | P18: MEASURED (21 calls): ~350-620 in / ~50-630 out. Once per deal; short headline and next action.
B19: Total per document | G19: =SUMPRODUCT((D7:D18<>"Code")*G7:G18) -> 6.2 | H19: =SUMPRODUCT((D7:D18<>"Code")*H7:H18) -> 4.2 | I19: =SUMPRODUCT((D7:D18<>"Code")*I7:I18) -> 3.2 | M19: =SUM(M7:M18) -> 0.261081 | N19: =SUM(N7:N18) -> 0.242856 | O19: =SUM(O7:O18) -> 0.022881 | P19: G/H/I = number of model calls (code steps excluded). M/N/O = AI cost per document type.
B20: Cost per full-review DEAL (main + supporting docs) | M20: =M19+N19*Inputs!$C$11 -> 0.503937 | P20: Main agreement + supporting documents per deal (Inputs).
B22: Tokens by model tier (used by the model comparison below)
B23: Document type | E23: Strong in | F23: Strong out | G23: Fast in | H23: Fast out
B24: Main agreement | E24: =SUMPRODUCT((D7:D18="Strong")*E7:E18*G7:G18) -> 38550 | F24: =SUMPRODUCT((D7:D18="Strong")*F7:F18*G7:G18) -> 21350 | G24: =SUMPRODUCT((D7:D18="Fast")*E7:E18*G7:G18) -> 10020 | H24: =SUMPRODUCT((D7:D18="Fast")*F7:F18*G7:G18) -> 3240
B25: Supporting document | E25: =SUMPRODUCT((D7:D18="Strong")*E7:E18*H7:H18) -> 37500 | F25: =SUMPRODUCT((D7:D18="Strong")*F7:F18*H7:H18) -> 19500 | G25: =SUMPRODUCT((D7:D18="Fast")*E7:E18*H7:H18) -> 10020 | H25: =SUMPRODUCT((D7:D18="Fast")*F7:F18*H7:H18) -> 3240
B26: NDA | E26: =SUMPRODUCT((D7:D18="Strong")*E7:E18*I7:I18) -> 1850 | F26: =SUMPRODUCT((D7:D18="Strong")*F7:F18*I7:I18) -> 1000 | G26: =SUMPRODUCT((D7:D18="Fast")*E7:E18*I7:I18) -> 10020 | H26: =SUMPRODUCT((D7:D18="Fast")*F7:F18*I7:I18) -> 3240
B28: B. Register and seller workloads
B29: Workload | C29: Feature / FR | D29: Model tier | E29: Input tokens per unit | F29: Output tokens per unit (incl. thinking) | G29: Units per month | L29: Cost per unit ($) | M29: Cost per month ($) | P29: Basis
B30: Register update: extract a newly signed contract | C30: F1 · FR-1 | D30: Strong | E30: 2621 | F30: 7850 | G30: =Inputs!$C$15 -> 6 | L30: =E30*IF(D30="Strong",Inputs!$C$43,Inputs!$C$45)/1000000+F30*IF(D30="Strong",Inputs!$C$44,Inputs!$C$46)/1000000 -> 0.0745815 | M30: =L30*G30 -> 0.447489 | P30: MEASURED on the prototype: 17 signed contracts → 44,557 in / 133,451 out tokens (avg 2,621 / 7,850). Output is mostly thinking: the model reasons about scope, affiliates and expiry.
B31: Seller deal check | C31: F7 · FR-13 | D31: Fast | E31: 3000 | F31: 800 | G31: =Inputs!$C$16 -> 12 | L31: =E31*IF(D31="Strong",Inputs!$C$43,Inputs!$C$45)/1000000+F31*IF(D31="Strong",Inputs!$C$44,Inputs!$C$46)/1000000 -> 0.0029 | M31: =L31*G31 -> 0.0348 | P31: Form facts + filtered register entries + prompt; rate and region checks are code.
B33: C. Eval runs (quality checks)
B34: Cost of one full eval-set run (50 cases) | L34: =(Inputs!$C$25*Inference!$M$19+Inputs!$C$26*Inference!$N$19+Inputs!$C$27*Inference!$O$19)*Inputs!$C$24 -> 3.18339 | P34: 11 main agreements + 1 supporting document + 3 NDAs, uncached, × repeats. Linking, access and register cases are code: $0.
B36: D. Monthly inference cost
B37: Line | E37: Units per month (today) | L37: Cost per unit ($) | M37: Cost per month ($) | P37: How it's calculated
B38: Full-review deals (incl. re-check versions) | E38: =Inputs!$C$9*(1+(Inputs!$C$13-1)*(1-Inputs!$C$14)) -> 4.55 | L38: =Inference!$M$20 -> 0.503937 | M38: =E38*L38 -> 2.2929134 | P38: Full-review deals × (1 + extra versions × share not cached) × cost per deal
B39: NDA fast-lane reviews (incl. re-checks) | E39: =Inputs!$C$10*(1+(Inputs!$C$13-1)*(1-Inputs!$C$14)) -> 5.85 | L39: =Inference!$O$19 -> 0.022881 | M39: =E39*L39 -> 0.13385385 | P39: Same version factor
B40: Register updates (new signings) | E40: =Inputs!$C$15 -> 6 | L40: =Inference!$L$30 -> 0.0745815 | M40: =E40*L40 -> 0.447489
B41: Seller deal checks | E41: =Inputs!$C$16 -> 12 | L41: =Inference!$L$31 -> 0.0029 | M41: =E41*L41 -> 0.0348
B42: Eval-set runs | E42: =Inputs!$C$23 -> 4 | L42: =Inference!$L$34 -> 3.18339 | M42: =E42*L42 -> 12.73356 | P42: Doesn't grow with deal volume
B43: Total inference cost per month (today's volume) | M43: =SUM(M38:M42) -> 15.642616
B44: Total inference cost per month (growth scenario) | M44: =SUM(M38:M41)*Inputs!$C$17/Inputs!$C$6+M42 -> 20.0062 | P44: Reviews, signings and seller checks scale with deal volume; eval runs stay the same.
B45: Average AI cost per deal, excl. eval runs (today) | M45: =SUM(M38:M41)/Inputs!$C$6 -> 0.36363203
B47: E. One-time: register build from all past signed contracts
...

Sheet Embeddings
B2: Embeddings: clause index for similar past clauses (FR-22)
B3: Unlike a RAG chatbot, we embed SIGNED CONTRACT CLAUSES only (no FAQs/tickets/PDFs), plus the key clauses of each document under review as queries. The conflict check uses structured filters, not embeddings.
B5: A. Clause index build (one-time) | E5: B. New signed contracts (monthly)
B6: Component | C6: Quantity | E6: Component | F6: Quantity
B7: Signed contracts indexed | C7: 17 | E7: New contracts signed per month | F7: =Inputs!$C$15 -> 6
B8: Clause chunks (measured) | C8: 231 | E8: Tokens per signed contract | F8: =C11 -> 977.23529
B9: Embedding tokens (measured) | C9: 16613 | E9: Tokens per month | F9: =F7*F8 -> 5863.4118
B10: Tokens per clause | C10: =C9/C8 -> 71.917749 | E10: Cost per 1M tokens ($) | F10: =Inputs!$C$37 -> 0.15
B11: Tokens per signed contract | C11: =C9/C7 -> 977.23529 | E11: Monthly cost ($) | F11: =F9*F10/1000000 -> 0.00087951176
B12: Cost per 1M tokens ($) | C12: =Inputs!$C$37 -> 0.15
B13: Total build cost ($) | C13: =C9*C12/1000000 -> 0.00249195
B15: C. Query embeddings (per document reviewed) | E15: D. Totals
B16: Component | C16: Quantity | E16: Component | F16: Cost ($)
B17: Key clauses embedded per document | C17: 10 | E17: One-time: clause index build | F17: =C13 -> 0.00249195
B18: Tokens per clause | C18: =C10 -> 71.917749 | E18: Monthly: new signed contracts | F18: =F11 -> 0.00087951176
B19: Documents reviewed per month (main + supporting, incl. re-checks) | C19: =Inference!$E$38*(1+Inputs!$C$11) -> 9.1 | E19: Monthly: query embeddings | F19: =C22 -> 0.00098167727
B20: Tokens per month | C20: =C17*C18*C19 -> 6544.5152 | E20: Total embeddings per month | F20: =F18+F19 -> 0.001861189
B21: Cost per 1M tokens ($) | C21: =Inputs!$C$37 -> 0.15 | E21: Index build at 500 contracts (scale check) | F21: =C11*500*C12/1000000 -> 0.073292647
B22: Monthly cost ($) | C22: =C20*C21/1000000 -> 0.00098167727
B24: Source: data/runs/clause-index-2026-10-04-18-41-03.json (231 chunks, 16,613 tokens, gemini-embedding-001). NDAs skip the similar-clauses step, so they aren't embedded. Storage: JSON file in the prototype ($0); Postgres + vector extension in production (Inputs §5).

Sheet Cost Savings
B2: Cost savings: what AtliQ saves by reviewing with Yours Legally
B3: The product doesn't replace an employee; it gives back the CEO's time, cuts seller chasing and avoids some counsel fees. Time is valued in money via the hourly rates on the Inputs sheet.
B5: A. Karandeep's review time today (manual)
B6: Component | C6: Quantity | D6: Source / assumption
B7: Full reviews per month | C7: =Inputs!$C$9 -> 3.5 | D7: Inputs sheet
B8: Hours per standard contract review today | C8: 2 | D8: Client meeting 2: about 2 hours per standard contract.
B9: Hours per complex contract review today (2 to 3 passes) | C9: 7 | D9: Client meeting 2: complex contracts take 2 to 3 passes, about 6 to 8 hours.
B10: Share of contracts that are complex | C10: 0.3 | D10: Assumption: about 1 in 3 client or partner contracts needs several passes.
B11: Average hours per full review today | C11: =C8*(1-C10)+C9*C10 -> 3.5 | D11: Weighted average of standard and complex reviews.
B12: NDA reviews per month | C12: =Inputs!$C$10 -> 4.5 | D12: Inputs sheet
B13: Hours per NDA today | C13: 0.5 | D13: Assumption: reading + checking 'if mutual'. Today this is often skipped, which is the risk (FinServe).
B14: Revised drafts per month | C14: =(Inputs!$C$13-1)*Inputs!$C$6 -> 4 | D14: Inputs: brief versions per contract
B15: Hours per revised draft today | C15: 1 | D15: Assumption: re-reading a changed contract from scratch.
B16: Karandeep's hours per month on contracts (today) | C16: =C7*C11+C12*C13+C14*C15 -> 18.5
B18: B. Karandeep's review time with Yours Legally
B19: Component | C19: Quantity | D19: Source / assumption
B20: Minutes per full review (deciding from the brief) | C20: 30 | D20: PRD §12 target: under 30 minutes of his time per contract (complex ones may need more; see sensitivity).
B21: Minutes per NDA brief | C21: 5 | D21: Assumption: fast-lane brief read + decision.
B22: Minutes per re-check version | C22: 10 | D22: Assumption: only New / Still open / Resolved items need attention (FR-17).
B23: Register entries to verify per month | C23: =Inputs!$C$15*57/17 -> 20.117647 | D23: Measured: 57 entries from 17 signed contracts (~3.4 per contract).
B24: Minutes per register verification | C24: 1 | D24: PRD §5: ~1 minute per entry, source clause shown alongside.
B25: Karandeep's hours per month with Yours Legally | C25: =('Cost Savings'!$C$7*C20+'Cost Savings'!$C$12*C21+'Cost Savings'!$C$14*C22+C23*C24)/60 -> 3.1269608
B27: C. Karandeep's time saved
B28: Component | C28: Quantity | D28: Source / assumption
B29: Hours saved per month | C29: ='Cost Savings'!$C$16-'Cost Savings'!$C$25 -> 15.373039 | D29: A − B
B30: Share of his contract time given back | C30: =IF('Cost Savings'!$C$16=0,0,('Cost Savings'!$C$16-'Cost Savings'!$C$25)/'Cost Savings'!$C$16) -> 0.83097509
B31: Value of one hour ($) | C31: =Inputs!$C$57 -> 60 | D31: Inputs (key assumption)
B32: Value of Karandeep's time saved per month ($) | C32: =C29*C31 -> 922.38235
B34: D. Sellers' chasing and waiting time
B35: Component | C35: Quantity | D35: Source / assumption
B36: Deals per month | C36: =Inputs!$C$6 -> 8 | D36: Inputs
B37: Seller hours per deal chasing status today | C37: 1.5 | D37: Assumption: 22 Sep, three sellers chased Karandeep the same morning; no status anywhere.
B38: Seller hours per deal with the queue and heads-up | C38: 0.25 | D38: Assumption: status, due-in and 'waiting for' are visible (FR-14).
B39: Seller hourly cost ($) | C39: =Inputs!$C$58 -> 20 | D39: Inputs
B40: Seller time cost today ($) | C40: =C36*C37*C39 -> 240
B41: Seller time cost with Yours Legally ($) | C41: =C36*C38*C39 -> 40
B42: Value of seller time saved per month ($) | C42: =C40-C41 -> 200
B44: E. Outside counsel
B45: Component | C45: Quantity | D45: Source / assumption
B46: Counsel matters per month today | C46: 0.5 | D46: Assumption: about one every two months (Gulf Crown ₹1.2L; CareBridge $3,800).
...

Sheet Method & Sources
B2: How this estimate works
B4: Why this differs from the RAG template | C4: The template prices a chatbot: one model call per user query, plus embeddings for FAQs, tickets and PDFs. Yours Legally is a review pipeline: each contract triggers a fixed sequence of steps. AI is used only to extract, judge and word; rule checks and the verdict are code ($0). So the unit is 'one contract review', not 'one query'.
B5: Do we need inference? | C5: Yes. Inference is every model call: extracting facts, the conflict reasoning, the playbook check, the NDA check, 'how it differs' lines, notes facts, the brief wording, register extraction and seller checks. The template's 'Inference' sheet becomes our per-step table.
B6: 'Tool call' cost | C6: Each pipeline step that calls the model costs (input tokens × input price) + (output tokens × output price). Gemini bills THINKING tokens as output, which is why output dominates: register extraction measured ~3 output tokens per input token. Code steps (gate rules, vector search, required documents, verdict) cost nothing per call.
B7: Batch API | C7: Gemini processes a batch of requests as one job within ~24 h at 50% of the price. Used only for the one-time register build, where nobody waits.
B8: Embeddings | C8: Only the signed-contract clause index (one-time, then each new signing) and ~10 key clauses per review as queries. Measured: 16,613 tokens for the whole index, i.e. well under one cent.
B9: Cost savings = time savings | C9: We don't replace a salaried agent. We value hours given back: Karandeep's review hours × the value of his hour, sellers' chasing hours × their hourly cost, and fewer/cheaper counsel matters. Risk avoided (Brightwater-type incidents) and revenue protected (queue-lost deals) are shown separately as expected values, so the base case stays conservative.
B10: Maintenance (not modelled) | C10: Someone must maintain prompts, evals and the register. In real projects this engineering time often costs more than the AI. Mention it in the deck as a known cost.
B11: Biggest levers to sanity-check | C11: 1) Value of Karandeep's hour. 2) Hours per full review today (3–4 h from the dataset). 3) Counsel matters per month. Model choice barely moves the total: AI cost is cents per contract; hosting is the largest running cost.
B12: Measured inputs | C12: data/runs/register-2026-10-04-18-34-55.json (17 docs, 44,557 in / 133,451 out); data/runs/clause-index-2026-10-04-18-41-03.json (231 chunks, 16,613 tokens); data/runs/review-2026-10-05-04-06-35.json (partial: 429 rate limits).
B13: Prices | C13: Gemini API pricing page (ai.google.dev/gemini-api/docs/pricing), checked 5 Oct 2026: 3.5 Flash $1.50/$9.00; 3.5 Flash-Lite $0.30/$2.50; 3.8 Flash $0.75/$3.75 to 31 Dec 2026 then $1.50/$7.50; 3.1 Flash-Lite $0.25/$1.50; 3 Flash Preview $0.50/$3.00; Batch API 50% off. gemini-embedding-001 $0.15 per 1M input tokens (Google Developers Blog, Gemini Embedding GA).
B14: Client and dataset facts used | C14: Client interview: 3-4 contracts + 4-5 NDAs a month, about 2 hours per standard review and 6-8 hours for complex ones, real contracts 10-15 pages, turnaround 1 week to 1 month. Dataset: Brightwater $9k + $14.2k + ~2 weeks; counsel ₹1.2L for Gulf Crown; CareBridge BAA review $3,800; ShopSwift $55k waited 9 days; 57 register entries from 17 signed contracts.
B15: Free tier vs paid | C15: The prototype runs on Gemini's free tier, which rate-limits per minute and per day (the build pause). Production would use the paid tier; costs here use paid prices.
